INFO:     Will watch for changes in these directories: ['C:\\Users\\sandv\\Desktop\\Outscaled2\\backend']
INFO:     Uvicorn running on http://0.0.0.0:8000 (Press CTRL+C to quit)
INFO:     Started reloader process [28620] using StatReload
WARNING:app.utils.data_processor:Data files not found. Using empty DataFrame for testing.
INFO:app.models.prediction_model:Training prediction model...
WARNING:app.utils.data_processor:Data files not found. Using empty DataFrame for testing.
Process SpawnProcess-1:
Traceback (most recent call last):
  File "C:\Python313\Lib\multiprocessing\process.py", line 313, in _bootstrap
    self.run()
    ~~~~~~~~^^
  File "C:\Python313\Lib\multiprocessing\process.py", line 108, in run
    self._target(*self._args, **self._kwargs)
    ~~~~~~~~~~~~^^^^^^^^^^^^^^^^^^^^^^^^^^^^^
  File "C:\Users\sandv\AppData\Roaming\Python\Python313\site-packages\uvicorn\_subprocess.py", line 80, in subprocess_started
    target(sockets=sockets)
    ~~~~~~^^^^^^^^^^^^^^^^^
  File "C:\Users\sandv\AppData\Roaming\Python\Python313\site-packages\uvicorn\server.py", line 66, in run
    return asyncio.run(self.serve(sockets=sockets))
           ~~~~~~~~~~~^^^^^^^^^^^^^^^^^^^^^^^^^^^^^
  File "C:\Python313\Lib\asyncio\runners.py", line 194, in run
    return runner.run(main)
           ~~~~~~~~~~^^^^^^
  File "C:\Python313\Lib\asyncio\runners.py", line 118, in run
    return self._loop.run_until_complete(task)
           ~~~~~~~~~~~~~~~~~~~~~~~~~~~~~^^^^^^
  File "C:\Python313\Lib\asyncio\base_events.py", line 720, in run_until_complete
    return future.result()
           ~~~~~~~~~~~~~^^
  File "C:\Users\sandv\AppData\Roaming\Python\Python313\site-packages\uvicorn\server.py", line 70, in serve
    await self._serve(sockets)
  File "C:\Users\sandv\AppData\Roaming\Python\Python313\site-packages\uvicorn\server.py", line 77, in _serve
    config.load()
    ~~~~~~~~~~~^^
  File "C:\Users\sandv\AppData\Roaming\Python\Python313\site-packages\uvicorn\config.py", line 435, in load
    self.loaded_app = import_from_string(self.app)
                      ~~~~~~~~~~~~~~~~~~^^^^^^^^^^
  File "C:\Users\sandv\AppData\Roaming\Python\Python313\site-packages\uvicorn\importer.py", line 19, in import_from_string
    module = importlib.import_module(module_str)
  File "C:\Python313\Lib\importlib\__init__.py", line 88, in import_module
    return _bootstrap._gcd_import(name[level:], package, level)
           ~~~~~~~~~~~~~~~~~~~~~~^^^^^^^^^^^^^^^^^^^^^^^^^^^^^^
  File "<frozen importlib._bootstrap>", line 1387, in _gcd_import
  File "<frozen importlib._bootstrap>", line 1360, in _find_and_load
  File "<frozen importlib._bootstrap>", line 1331, in _find_and_load_unlocked
  File "<frozen importlib._bootstrap>", line 935, in _load_unlocked
  File "<frozen importlib._bootstrap_external>", line 1026, in exec_module
  File "<frozen importlib._bootstrap>", line 488, in _call_with_frames_removed
  File "C:\Users\sandv\Desktop\Outscaled2\backend\app\main.py", line 12, in <module>
    prediction_model = PredictionModel()
  File "C:\Users\sandv\Desktop\Outscaled2\backend\app\models\prediction_model.py", line 19, in __init__
    self._train_model()
    ~~~~~~~~~~~~~~~~~^^
  File "C:\Users\sandv\Desktop\Outscaled2\backend\app\models\prediction_model.py", line 26, in _train_model
    X, y, sample_weights = self._generate_real_training_data()
                           ~~~~~~~~~~~~~~~~~~~~~~~~~~~~~~~~~^^
  File "C:\Users\sandv\Desktop\Outscaled2\backend\app\models\prediction_model.py", line 88, in _generate_real_training_data
    all_players = data_processor.get_all_players()
  File "C:\Users\sandv\Desktop\Outscaled2\backend\app\utils\data_processor.py", line 811, in get_all_players
    all_players = combined_data['playername'].dropna().unique().tolist()
                  ~~~~~~~~~~~~~^^^^^^^^^^^^^^
  File "C:\Users\sandv\AppData\Roaming\Python\Python313\site-packages\pandas\core\frame.py", line 4107, in __getitem__
    indexer = self.columns.get_loc(key)
  File "C:\Users\sandv\AppData\Roaming\Python\Python313\site-packages\pandas\core\indexes\range.py", line 417, in get_loc
    raise KeyError(key)
KeyError: 'playername'
WARNING:  StatReload detected changes in 'app\models\prediction_model.py'. Reloading...
WARNING:app.utils.data_processor:Data files not found. Using empty DataFrame for testing.
INFO:app.models.prediction_model:Training prediction model...
WARNING:app.utils.data_processor:Data files not found. Using empty DataFrame for testing.
Process SpawnProcess-2:
Traceback (most recent call last):
  File "C:\Python313\Lib\multiprocessing\process.py", line 313, in _bootstrap
    self.run()
    ~~~~~~~~^^
  File "C:\Python313\Lib\multiprocessing\process.py", line 108, in run
    self._target(*self._args, **self._kwargs)
    ~~~~~~~~~~~~^^^^^^^^^^^^^^^^^^^^^^^^^^^^^
  File "C:\Users\sandv\AppData\Roaming\Python\Python313\site-packages\uvicorn\_subprocess.py", line 80, in subprocess_started
    target(sockets=sockets)
    ~~~~~~^^^^^^^^^^^^^^^^^
  File "C:\Users\sandv\AppData\Roaming\Python\Python313\site-packages\uvicorn\server.py", line 66, in run
    return asyncio.run(self.serve(sockets=sockets))
           ~~~~~~~~~~~^^^^^^^^^^^^^^^^^^^^^^^^^^^^^
  File "C:\Python313\Lib\asyncio\runners.py", line 194, in run
    return runner.run(main)
           ~~~~~~~~~~^^^^^^
  File "C:\Python313\Lib\asyncio\runners.py", line 118, in run
    return self._loop.run_until_complete(task)
           ~~~~~~~~~~~~~~~~~~~~~~~~~~~~~^^^^^^
  File "C:\Python313\Lib\asyncio\base_events.py", line 720, in run_until_complete
    return future.result()
           ~~~~~~~~~~~~~^^
  File "C:\Users\sandv\AppData\Roaming\Python\Python313\site-packages\uvicorn\server.py", line 70, in serve
    await self._serve(sockets)
  File "C:\Users\sandv\AppData\Roaming\Python\Python313\site-packages\uvicorn\server.py", line 77, in _serve
    config.load()
    ~~~~~~~~~~~^^
  File "C:\Users\sandv\AppData\Roaming\Python\Python313\site-packages\uvicorn\config.py", line 435, in load
    self.loaded_app = import_from_string(self.app)
                      ~~~~~~~~~~~~~~~~~~^^^^^^^^^^
  File "C:\Users\sandv\AppData\Roaming\Python\Python313\site-packages\uvicorn\importer.py", line 19, in import_from_string
    module = importlib.import_module(module_str)
  File "C:\Python313\Lib\importlib\__init__.py", line 88, in import_module
    return _bootstrap._gcd_import(name[level:], package, level)
           ~~~~~~~~~~~~~~~~~~~~~~^^^^^^^^^^^^^^^^^^^^^^^^^^^^^^
  File "<frozen importlib._bootstrap>", line 1387, in _gcd_import
  File "<frozen importlib._bootstrap>", line 1360, in _find_and_load
  File "<frozen importlib._bootstrap>", line 1331, in _find_and_load_unlocked
  File "<frozen importlib._bootstrap>", line 935, in _load_unlocked
  File "<frozen importlib._bootstrap_external>", line 1026, in exec_module
  File "<frozen importlib._bootstrap>", line 488, in _call_with_frames_removed
  File "C:\Users\sandv\Desktop\Outscaled2\backend\app\main.py", line 12, in <module>
    prediction_model = PredictionModel()
  File "C:\Users\sandv\Desktop\Outscaled2\backend\app\models\prediction_model.py", line 19, in __init__
    self._train_model()
    ~~~~~~~~~~~~~~~~~^^
  File "C:\Users\sandv\Desktop\Outscaled2\backend\app\models\prediction_model.py", line 26, in _train_model
    X, y, sample_weights = self._generate_real_training_data()
                           ~~~~~~~~~~~~~~~~~~~~~~~~~~~~~~~~~^^
  File "C:\Users\sandv\Desktop\Outscaled2\backend\app\models\prediction_model.py", line 88, in _generate_real_training_data
    all_players = data_processor.get_all_players()
  File "C:\Users\sandv\Desktop\Outscaled2\backend\app\utils\data_processor.py", line 811, in get_all_players
    all_players = combined_data['playername'].dropna().unique().tolist()
                  ~~~~~~~~~~~~~^^^^^^^^^^^^^^
  File "C:\Users\sandv\AppData\Roaming\Python\Python313\site-packages\pandas\core\frame.py", line 4107, in __getitem__
    indexer = self.columns.get_loc(key)
  File "C:\Users\sandv\AppData\Roaming\Python\Python313\site-packages\pandas\core\indexes\range.py", line 417, in get_loc
    raise KeyError(key)
KeyError: 'playername'
WARNING:  StatReload detected changes in 'app\models\prediction_model.py'. Reloading...
WARNING:app.utils.data_processor:Data files not found. Using empty DataFrame for testing.
INFO:app.models.prediction_model:Training prediction model...
WARNING:app.utils.data_processor:Data files not found. Using empty DataFrame for testing.
Process SpawnProcess-3:
Traceback (most recent call last):
  File "C:\Python313\Lib\multiprocessing\process.py", line 313, in _bootstrap
    self.run()
    ~~~~~~~~^^
  File "C:\Python313\Lib\multiprocessing\process.py", line 108, in run
    self._target(*self._args, **self._kwargs)
    ~~~~~~~~~~~~^^^^^^^^^^^^^^^^^^^^^^^^^^^^^
  File "C:\Users\sandv\AppData\Roaming\Python\Python313\site-packages\uvicorn\_subprocess.py", line 80, in subprocess_started
    target(sockets=sockets)
    ~~~~~~^^^^^^^^^^^^^^^^^
  File "C:\Users\sandv\AppData\Roaming\Python\Python313\site-packages\uvicorn\server.py", line 66, in run
    return asyncio.run(self.serve(sockets=sockets))
           ~~~~~~~~~~~^^^^^^^^^^^^^^^^^^^^^^^^^^^^^
  File "C:\Python313\Lib\asyncio\runners.py", line 194, in run
    return runner.run(main)
           ~~~~~~~~~~^^^^^^
  File "C:\Python313\Lib\asyncio\runners.py", line 118, in run
    return self._loop.run_until_complete(task)
           ~~~~~~~~~~~~~~~~~~~~~~~~~~~~~^^^^^^
  File "C:\Python313\Lib\asyncio\base_events.py", line 720, in run_until_complete
    return future.result()
           ~~~~~~~~~~~~~^^
  File "C:\Users\sandv\AppData\Roaming\Python\Python313\site-packages\uvicorn\server.py", line 70, in serve
    await self._serve(sockets)
  File "C:\Users\sandv\AppData\Roaming\Python\Python313\site-packages\uvicorn\server.py", line 77, in _serve
    config.load()
    ~~~~~~~~~~~^^
  File "C:\Users\sandv\AppData\Roaming\Python\Python313\site-packages\uvicorn\config.py", line 435, in load
    self.loaded_app = import_from_string(self.app)
                      ~~~~~~~~~~~~~~~~~~^^^^^^^^^^
  File "C:\Users\sandv\AppData\Roaming\Python\Python313\site-packages\uvicorn\importer.py", line 19, in import_from_string
    module = importlib.import_module(module_str)
  File "C:\Python313\Lib\importlib\__init__.py", line 88, in import_module
    return _bootstrap._gcd_import(name[level:], package, level)
           ~~~~~~~~~~~~~~~~~~~~~~^^^^^^^^^^^^^^^^^^^^^^^^^^^^^^
  File "<frozen importlib._bootstrap>", line 1387, in _gcd_import
  File "<frozen importlib._bootstrap>", line 1360, in _find_and_load
  File "<frozen importlib._bootstrap>", line 1331, in _find_and_load_unlocked
  File "<frozen importlib._bootstrap>", line 935, in _load_unlocked
  File "<frozen importlib._bootstrap_external>", line 1026, in exec_module
  File "<frozen importlib._bootstrap>", line 488, in _call_with_frames_removed
  File "C:\Users\sandv\Desktop\Outscaled2\backend\app\main.py", line 12, in <module>
    prediction_model = PredictionModel()
  File "C:\Users\sandv\Desktop\Outscaled2\backend\app\models\prediction_model.py", line 19, in __init__
    self._train_model()
    ~~~~~~~~~~~~~~~~~^^
  File "C:\Users\sandv\Desktop\Outscaled2\backend\app\models\prediction_model.py", line 26, in _train_model
    X, y, sample_weights = self._generate_real_training_data()
                           ~~~~~~~~~~~~~~~~~~~~~~~~~~~~~~~~~^^
  File "C:\Users\sandv\Desktop\Outscaled2\backend\app\models\prediction_model.py", line 88, in _generate_real_training_data
    all_players = data_processor.get_all_players()
  File "C:\Users\sandv\Desktop\Outscaled2\backend\app\utils\data_processor.py", line 811, in get_all_players
    all_players = combined_data['playername'].dropna().unique().tolist()
                  ~~~~~~~~~~~~~^^^^^^^^^^^^^^
  File "C:\Users\sandv\AppData\Roaming\Python\Python313\site-packages\pandas\core\frame.py", line 4107, in __getitem__
    indexer = self.columns.get_loc(key)
  File "C:\Users\sandv\AppData\Roaming\Python\Python313\site-packages\pandas\core\indexes\range.py", line 417, in get_loc
    raise KeyError(key)
KeyError: 'playername'
WARNING:  StatReload detected changes in 'app\models\prediction_model.py'. Reloading...
WARNING:app.utils.data_processor:Data files not found. Using empty DataFrame for testing.
INFO:app.models.prediction_model:Training prediction model...
WARNING:app.utils.data_processor:Data files not found. Using empty DataFrame for testing.
Process SpawnProcess-4:
Traceback (most recent call last):
  File "C:\Python313\Lib\multiprocessing\process.py", line 313, in _bootstrap
    self.run()
    ~~~~~~~~^^
  File "C:\Python313\Lib\multiprocessing\process.py", line 108, in run
    self._target(*self._args, **self._kwargs)
    ~~~~~~~~~~~~^^^^^^^^^^^^^^^^^^^^^^^^^^^^^
  File "C:\Users\sandv\AppData\Roaming\Python\Python313\site-packages\uvicorn\_subprocess.py", line 80, in subprocess_started
    target(sockets=sockets)
    ~~~~~~^^^^^^^^^^^^^^^^^
  File "C:\Users\sandv\AppData\Roaming\Python\Python313\site-packages\uvicorn\server.py", line 66, in run
    return asyncio.run(self.serve(sockets=sockets))
           ~~~~~~~~~~~^^^^^^^^^^^^^^^^^^^^^^^^^^^^^
  File "C:\Python313\Lib\asyncio\runners.py", line 194, in run
    return runner.run(main)
           ~~~~~~~~~~^^^^^^
  File "C:\Python313\Lib\asyncio\runners.py", line 118, in run
    return self._loop.run_until_complete(task)
           ~~~~~~~~~~~~~~~~~~~~~~~~~~~~~^^^^^^
  File "C:\Python313\Lib\asyncio\base_events.py", line 720, in run_until_complete
    return future.result()
           ~~~~~~~~~~~~~^^
  File "C:\Users\sandv\AppData\Roaming\Python\Python313\site-packages\uvicorn\server.py", line 70, in serve
    await self._serve(sockets)
  File "C:\Users\sandv\AppData\Roaming\Python\Python313\site-packages\uvicorn\server.py", line 77, in _serve
    config.load()
    ~~~~~~~~~~~^^
  File "C:\Users\sandv\AppData\Roaming\Python\Python313\site-packages\uvicorn\config.py", line 435, in load
    self.loaded_app = import_from_string(self.app)
                      ~~~~~~~~~~~~~~~~~~^^^^^^^^^^
  File "C:\Users\sandv\AppData\Roaming\Python\Python313\site-packages\uvicorn\importer.py", line 19, in import_from_string
    module = importlib.import_module(module_str)
  File "C:\Python313\Lib\importlib\__init__.py", line 88, in import_module
    return _bootstrap._gcd_import(name[level:], package, level)
           ~~~~~~~~~~~~~~~~~~~~~~^^^^^^^^^^^^^^^^^^^^^^^^^^^^^^
  File "<frozen importlib._bootstrap>", line 1387, in _gcd_import
  File "<frozen importlib._bootstrap>", line 1360, in _find_and_load
  File "<frozen importlib._bootstrap>", line 1331, in _find_and_load_unlocked
  File "<frozen importlib._bootstrap>", line 935, in _load_unlocked
  File "<frozen importlib._bootstrap_external>", line 1026, in exec_module
  File "<frozen importlib._bootstrap>", line 488, in _call_with_frames_removed
  File "C:\Users\sandv\Desktop\Outscaled2\backend\app\main.py", line 12, in <module>
    prediction_model = PredictionModel()
  File "C:\Users\sandv\Desktop\Outscaled2\backend\app\models\prediction_model.py", line 19, in __init__
    self._train_model()
    ~~~~~~~~~~~~~~~~~^^
  File "C:\Users\sandv\Desktop\Outscaled2\backend\app\models\prediction_model.py", line 26, in _train_model
    X, y, sample_weights = self._generate_real_training_data()
                           ~~~~~~~~~~~~~~~~~~~~~~~~~~~~~~~~~^^
  File "C:\Users\sandv\Desktop\Outscaled2\backend\app\models\prediction_model.py", line 88, in _generate_real_training_data
    all_players = data_processor.get_all_players()
  File "C:\Users\sandv\Desktop\Outscaled2\backend\app\utils\data_processor.py", line 811, in get_all_players
    all_players = combined_data['playername'].dropna().unique().tolist()
                  ~~~~~~~~~~~~~^^^^^^^^^^^^^^
  File "C:\Users\sandv\AppData\Roaming\Python\Python313\site-packages\pandas\core\frame.py", line 4107, in __getitem__
    indexer = self.columns.get_loc(key)
  File "C:\Users\sandv\AppData\Roaming\Python\Python313\site-packages\pandas\core\indexes\range.py", line 417, in get_loc
    raise KeyError(key)
KeyError: 'playername'
WARNING:  StatReload detected changes in 'app\models\prediction_model.py'. Reloading...
WARNING:app.utils.data_processor:Data files not found. Using empty DataFrame for testing.
INFO:app.models.prediction_model:Training prediction model...
WARNING:app.utils.data_processor:Data files not found. Using empty DataFrame for testing.
Process SpawnProcess-5:
Traceback (most recent call last):
  File "C:\Python313\Lib\multiprocessing\process.py", line 313, in _bootstrap
    self.run()
    ~~~~~~~~^^
  File "C:\Python313\Lib\multiprocessing\process.py", line 108, in run
    self._target(*self._args, **self._kwargs)
    ~~~~~~~~~~~~^^^^^^^^^^^^^^^^^^^^^^^^^^^^^
  File "C:\Users\sandv\AppData\Roaming\Python\Python313\site-packages\uvicorn\_subprocess.py", line 80, in subprocess_started
    target(sockets=sockets)
    ~~~~~~^^^^^^^^^^^^^^^^^
  File "C:\Users\sandv\AppData\Roaming\Python\Python313\site-packages\uvicorn\server.py", line 66, in run
    return asyncio.run(self.serve(sockets=sockets))
           ~~~~~~~~~~~^^^^^^^^^^^^^^^^^^^^^^^^^^^^^
  File "C:\Python313\Lib\asyncio\runners.py", line 194, in run
    return runner.run(main)
           ~~~~~~~~~~^^^^^^
  File "C:\Python313\Lib\asyncio\runners.py", line 118, in run
    return self._loop.run_until_complete(task)
           ~~~~~~~~~~~~~~~~~~~~~~~~~~~~~^^^^^^
  File "C:\Python313\Lib\asyncio\base_events.py", line 720, in run_until_complete
    return future.result()
           ~~~~~~~~~~~~~^^
  File "C:\Users\sandv\AppData\Roaming\Python\Python313\site-packages\uvicorn\server.py", line 70, in serve
    await self._serve(sockets)
  File "C:\Users\sandv\AppData\Roaming\Python\Python313\site-packages\uvicorn\server.py", line 77, in _serve
    config.load()
    ~~~~~~~~~~~^^
  File "C:\Users\sandv\AppData\Roaming\Python\Python313\site-packages\uvicorn\config.py", line 435, in load
    self.loaded_app = import_from_string(self.app)
                      ~~~~~~~~~~~~~~~~~~^^^^^^^^^^
  File "C:\Users\sandv\AppData\Roaming\Python\Python313\site-packages\uvicorn\importer.py", line 19, in import_from_string
    module = importlib.import_module(module_str)
  File "C:\Python313\Lib\importlib\__init__.py", line 88, in import_module
    return _bootstrap._gcd_import(name[level:], package, level)
           ~~~~~~~~~~~~~~~~~~~~~~^^^^^^^^^^^^^^^^^^^^^^^^^^^^^^
  File "<frozen importlib._bootstrap>", line 1387, in _gcd_import
  File "<frozen importlib._bootstrap>", line 1360, in _find_and_load
  File "<frozen importlib._bootstrap>", line 1331, in _find_and_load_unlocked
  File "<frozen importlib._bootstrap>", line 935, in _load_unlocked
  File "<frozen importlib._bootstrap_external>", line 1026, in exec_module
  File "<frozen importlib._bootstrap>", line 488, in _call_with_frames_removed
  File "C:\Users\sandv\Desktop\Outscaled2\backend\app\main.py", line 12, in <module>
    prediction_model = PredictionModel()
  File "C:\Users\sandv\Desktop\Outscaled2\backend\app\models\prediction_model.py", line 19, in __init__
    self._train_model()
    ~~~~~~~~~~~~~~~~~^^
  File "C:\Users\sandv\Desktop\Outscaled2\backend\app\models\prediction_model.py", line 26, in _train_model
    X, y, sample_weights = self._generate_real_training_data()
                           ~~~~~~~~~~~~~~~~~~~~~~~~~~~~~~~~~^^
  File "C:\Users\sandv\Desktop\Outscaled2\backend\app\models\prediction_model.py", line 88, in _generate_real_training_data
    all_players = data_processor.get_all_players()
  File "C:\Users\sandv\Desktop\Outscaled2\backend\app\utils\data_processor.py", line 811, in get_all_players
    all_players = combined_data['playername'].dropna().unique().tolist()
                  ~~~~~~~~~~~~~^^^^^^^^^^^^^^
  File "C:\Users\sandv\AppData\Roaming\Python\Python313\site-packages\pandas\core\frame.py", line 4107, in __getitem__
    indexer = self.columns.get_loc(key)
  File "C:\Users\sandv\AppData\Roaming\Python\Python313\site-packages\pandas\core\indexes\range.py", line 417, in get_loc
    raise KeyError(key)
KeyError: 'playername'
WARNING:  StatReload detected changes in 'app\models\prediction_model.py'. Reloading...
WARNING:app.utils.data_processor:Data files not found. Using empty DataFrame for testing.
INFO:app.models.prediction_model:Training prediction model...
WARNING:app.utils.data_processor:Data files not found. Using empty DataFrame for testing.
Process SpawnProcess-6:
Traceback (most recent call last):
  File "C:\Python313\Lib\multiprocessing\process.py", line 313, in _bootstrap
    self.run()
    ~~~~~~~~^^
  File "C:\Python313\Lib\multiprocessing\process.py", line 108, in run
    self._target(*self._args, **self._kwargs)
    ~~~~~~~~~~~~^^^^^^^^^^^^^^^^^^^^^^^^^^^^^
  File "C:\Users\sandv\AppData\Roaming\Python\Python313\site-packages\uvicorn\_subprocess.py", line 80, in subprocess_started
    target(sockets=sockets)
    ~~~~~~^^^^^^^^^^^^^^^^^
  File "C:\Users\sandv\AppData\Roaming\Python\Python313\site-packages\uvicorn\server.py", line 66, in run
    return asyncio.run(self.serve(sockets=sockets))
           ~~~~~~~~~~~^^^^^^^^^^^^^^^^^^^^^^^^^^^^^
  File "C:\Python313\Lib\asyncio\runners.py", line 194, in run
    return runner.run(main)
           ~~~~~~~~~~^^^^^^
  File "C:\Python313\Lib\asyncio\runners.py", line 118, in run
    return self._loop.run_until_complete(task)
           ~~~~~~~~~~~~~~~~~~~~~~~~~~~~~^^^^^^
  File "C:\Python313\Lib\asyncio\base_events.py", line 720, in run_until_complete
    return future.result()
           ~~~~~~~~~~~~~^^
  File "C:\Users\sandv\AppData\Roaming\Python\Python313\site-packages\uvicorn\server.py", line 70, in serve
    await self._serve(sockets)
  File "C:\Users\sandv\AppData\Roaming\Python\Python313\site-packages\uvicorn\server.py", line 77, in _serve
    config.load()
    ~~~~~~~~~~~^^
  File "C:\Users\sandv\AppData\Roaming\Python\Python313\site-packages\uvicorn\config.py", line 435, in load
    self.loaded_app = import_from_string(self.app)
                      ~~~~~~~~~~~~~~~~~~^^^^^^^^^^
  File "C:\Users\sandv\AppData\Roaming\Python\Python313\site-packages\uvicorn\importer.py", line 19, in import_from_string
    module = importlib.import_module(module_str)
  File "C:\Python313\Lib\importlib\__init__.py", line 88, in import_module
    return _bootstrap._gcd_import(name[level:], package, level)
           ~~~~~~~~~~~~~~~~~~~~~~^^^^^^^^^^^^^^^^^^^^^^^^^^^^^^
  File "<frozen importlib._bootstrap>", line 1387, in _gcd_import
  File "<frozen importlib._bootstrap>", line 1360, in _find_and_load
  File "<frozen importlib._bootstrap>", line 1331, in _find_and_load_unlocked
  File "<frozen importlib._bootstrap>", line 935, in _load_unlocked
  File "<frozen importlib._bootstrap_external>", line 1026, in exec_module
  File "<frozen importlib._bootstrap>", line 488, in _call_with_frames_removed
  File "C:\Users\sandv\Desktop\Outscaled2\backend\app\main.py", line 12, in <module>
    prediction_model = PredictionModel()
  File "C:\Users\sandv\Desktop\Outscaled2\backend\app\models\prediction_model.py", line 19, in __init__
    self._train_model()
    ~~~~~~~~~~~~~~~~~^^
  File "C:\Users\sandv\Desktop\Outscaled2\backend\app\models\prediction_model.py", line 26, in _train_model
    X, y, sample_weights = self._generate_real_training_data()
                           ~~~~~~~~~~~~~~~~~~~~~~~~~~~~~~~~~^^
  File "C:\Users\sandv\Desktop\Outscaled2\backend\app\models\prediction_model.py", line 88, in _generate_real_training_data
    all_players = data_processor.get_all_players()
  File "C:\Users\sandv\Desktop\Outscaled2\backend\app\utils\data_processor.py", line 811, in get_all_players
    all_players = combined_data['playername'].dropna().unique().tolist()
                  ~~~~~~~~~~~~~^^^^^^^^^^^^^^
  File "C:\Users\sandv\AppData\Roaming\Python\Python313\site-packages\pandas\core\frame.py", line 4107, in __getitem__
    indexer = self.columns.get_loc(key)
  File "C:\Users\sandv\AppData\Roaming\Python\Python313\site-packages\pandas\core\indexes\range.py", line 417, in get_loc
    raise KeyError(key)
KeyError: 'playername'
WARNING:  StatReload detected changes in 'app\models\prediction_model.py'. Reloading...
WARNING:app.utils.data_processor:Data files not found. Using empty DataFrame for testing.
INFO:app.models.prediction_model:Training prediction model...
WARNING:app.utils.data_processor:Data files not found. Using empty DataFrame for testing.
Process SpawnProcess-7:
Traceback (most recent call last):
  File "C:\Python313\Lib\multiprocessing\process.py", line 313, in _bootstrap
    self.run()
    ~~~~~~~~^^
  File "C:\Python313\Lib\multiprocessing\process.py", line 108, in run
    self._target(*self._args, **self._kwargs)
    ~~~~~~~~~~~~^^^^^^^^^^^^^^^^^^^^^^^^^^^^^
  File "C:\Users\sandv\AppData\Roaming\Python\Python313\site-packages\uvicorn\_subprocess.py", line 80, in subprocess_started
    target(sockets=sockets)
    ~~~~~~^^^^^^^^^^^^^^^^^
  File "C:\Users\sandv\AppData\Roaming\Python\Python313\site-packages\uvicorn\server.py", line 66, in run
    return asyncio.run(self.serve(sockets=sockets))
           ~~~~~~~~~~~^^^^^^^^^^^^^^^^^^^^^^^^^^^^^
  File "C:\Python313\Lib\asyncio\runners.py", line 194, in run
    return runner.run(main)
           ~~~~~~~~~~^^^^^^
  File "C:\Python313\Lib\asyncio\runners.py", line 118, in run
    return self._loop.run_until_complete(task)
           ~~~~~~~~~~~~~~~~~~~~~~~~~~~~~^^^^^^
  File "C:\Python313\Lib\asyncio\base_events.py", line 720, in run_until_complete
    return future.result()
           ~~~~~~~~~~~~~^^
  File "C:\Users\sandv\AppData\Roaming\Python\Python313\site-packages\uvicorn\server.py", line 70, in serve
    await self._serve(sockets)
  File "C:\Users\sandv\AppData\Roaming\Python\Python313\site-packages\uvicorn\server.py", line 77, in _serve
    config.load()
    ~~~~~~~~~~~^^
  File "C:\Users\sandv\AppData\Roaming\Python\Python313\site-packages\uvicorn\config.py", line 435, in load
    self.loaded_app = import_from_string(self.app)
                      ~~~~~~~~~~~~~~~~~~^^^^^^^^^^
  File "C:\Users\sandv\AppData\Roaming\Python\Python313\site-packages\uvicorn\importer.py", line 19, in import_from_string
    module = importlib.import_module(module_str)
  File "C:\Python313\Lib\importlib\__init__.py", line 88, in import_module
    return _bootstrap._gcd_import(name[level:], package, level)
           ~~~~~~~~~~~~~~~~~~~~~~^^^^^^^^^^^^^^^^^^^^^^^^^^^^^^
  File "<frozen importlib._bootstrap>", line 1387, in _gcd_import
  File "<frozen importlib._bootstrap>", line 1360, in _find_and_load
  File "<frozen importlib._bootstrap>", line 1331, in _find_and_load_unlocked
  File "<frozen importlib._bootstrap>", line 935, in _load_unlocked
  File "<frozen importlib._bootstrap_external>", line 1026, in exec_module
  File "<frozen importlib._bootstrap>", line 488, in _call_with_frames_removed
  File "C:\Users\sandv\Desktop\Outscaled2\backend\app\main.py", line 12, in <module>
    prediction_model = PredictionModel()
  File "C:\Users\sandv\Desktop\Outscaled2\backend\app\models\prediction_model.py", line 19, in __init__
    self._train_model()
    ~~~~~~~~~~~~~~~~~^^
  File "C:\Users\sandv\Desktop\Outscaled2\backend\app\models\prediction_model.py", line 26, in _train_model
    X, y, sample_weights = self._generate_real_training_data()
                           ~~~~~~~~~~~~~~~~~~~~~~~~~~~~~~~~~^^
  File "C:\Users\sandv\Desktop\Outscaled2\backend\app\models\prediction_model.py", line 88, in _generate_real_training_data
    all_players = data_processor.get_all_players()
  File "C:\Users\sandv\Desktop\Outscaled2\backend\app\utils\data_processor.py", line 811, in get_all_players
    all_players = combined_data['playername'].dropna().unique().tolist()
                  ~~~~~~~~~~~~~^^^^^^^^^^^^^^
  File "C:\Users\sandv\AppData\Roaming\Python\Python313\site-packages\pandas\core\frame.py", line 4107, in __getitem__
    indexer = self.columns.get_loc(key)
  File "C:\Users\sandv\AppData\Roaming\Python\Python313\site-packages\pandas\core\indexes\range.py", line 417, in get_loc
    raise KeyError(key)
KeyError: 'playername'
WARNING:  StatReload detected changes in 'app\models\prediction_model.py'. Reloading...
WARNING:app.utils.data_processor:Data files not found. Using empty DataFrame for testing.
INFO:app.models.prediction_model:Training prediction model...
WARNING:app.utils.data_processor:Data files not found. Using empty DataFrame for testing.
Process SpawnProcess-8:
Traceback (most recent call last):
  File "C:\Python313\Lib\multiprocessing\process.py", line 313, in _bootstrap
    self.run()
    ~~~~~~~~^^
  File "C:\Python313\Lib\multiprocessing\process.py", line 108, in run
    self._target(*self._args, **self._kwargs)
    ~~~~~~~~~~~~^^^^^^^^^^^^^^^^^^^^^^^^^^^^^
  File "C:\Users\sandv\AppData\Roaming\Python\Python313\site-packages\uvicorn\_subprocess.py", line 80, in subprocess_started
    target(sockets=sockets)
    ~~~~~~^^^^^^^^^^^^^^^^^
  File "C:\Users\sandv\AppData\Roaming\Python\Python313\site-packages\uvicorn\server.py", line 66, in run
    return asyncio.run(self.serve(sockets=sockets))
           ~~~~~~~~~~~^^^^^^^^^^^^^^^^^^^^^^^^^^^^^
  File "C:\Python313\Lib\asyncio\runners.py", line 194, in run
    return runner.run(main)
           ~~~~~~~~~~^^^^^^
  File "C:\Python313\Lib\asyncio\runners.py", line 118, in run
    return self._loop.run_until_complete(task)
           ~~~~~~~~~~~~~~~~~~~~~~~~~~~~~^^^^^^
  File "C:\Python313\Lib\asyncio\base_events.py", line 720, in run_until_complete
    return future.result()
           ~~~~~~~~~~~~~^^
  File "C:\Users\sandv\AppData\Roaming\Python\Python313\site-packages\uvicorn\server.py", line 70, in serve
    await self._serve(sockets)
  File "C:\Users\sandv\AppData\Roaming\Python\Python313\site-packages\uvicorn\server.py", line 77, in _serve
    config.load()
    ~~~~~~~~~~~^^
  File "C:\Users\sandv\AppData\Roaming\Python\Python313\site-packages\uvicorn\config.py", line 435, in load
    self.loaded_app = import_from_string(self.app)
                      ~~~~~~~~~~~~~~~~~~^^^^^^^^^^
  File "C:\Users\sandv\AppData\Roaming\Python\Python313\site-packages\uvicorn\importer.py", line 19, in import_from_string
    module = importlib.import_module(module_str)
  File "C:\Python313\Lib\importlib\__init__.py", line 88, in import_module
    return _bootstrap._gcd_import(name[level:], package, level)
           ~~~~~~~~~~~~~~~~~~~~~~^^^^^^^^^^^^^^^^^^^^^^^^^^^^^^
  File "<frozen importlib._bootstrap>", line 1387, in _gcd_import
  File "<frozen importlib._bootstrap>", line 1360, in _find_and_load
  File "<frozen importlib._bootstrap>", line 1331, in _find_and_load_unlocked
  File "<frozen importlib._bootstrap>", line 935, in _load_unlocked
  File "<frozen importlib._bootstrap_external>", line 1026, in exec_module
  File "<frozen importlib._bootstrap>", line 488, in _call_with_frames_removed
  File "C:\Users\sandv\Desktop\Outscaled2\backend\app\main.py", line 12, in <module>
    prediction_model = PredictionModel()
  File "C:\Users\sandv\Desktop\Outscaled2\backend\app\models\prediction_model.py", line 19, in __init__
    self._train_model()
    ~~~~~~~~~~~~~~~~~^^
  File "C:\Users\sandv\Desktop\Outscaled2\backend\app\models\prediction_model.py", line 26, in _train_model
    X, y, sample_weights = self._generate_real_training_data()
                           ~~~~~~~~~~~~~~~~~~~~~~~~~~~~~~~~~^^
  File "C:\Users\sandv\Desktop\Outscaled2\backend\app\models\prediction_model.py", line 88, in _generate_real_training_data
    all_players = data_processor.get_all_players()
  File "C:\Users\sandv\Desktop\Outscaled2\backend\app\utils\data_processor.py", line 811, in get_all_players
    all_players = combined_data['playername'].dropna().unique().tolist()
                  ~~~~~~~~~~~~~^^^^^^^^^^^^^^
  File "C:\Users\sandv\AppData\Roaming\Python\Python313\site-packages\pandas\core\frame.py", line 4107, in __getitem__
    indexer = self.columns.get_loc(key)
  File "C:\Users\sandv\AppData\Roaming\Python\Python313\site-packages\pandas\core\indexes\range.py", line 417, in get_loc
    raise KeyError(key)
KeyError: 'playername'
WARNING:  StatReload detected changes in 'test_confidence_consistency.py'. Reloading...
WARNING:app.utils.data_processor:Data files not found. Using empty DataFrame for testing.
INFO:app.models.prediction_model:Training prediction model...
WARNING:app.utils.data_processor:Data files not found. Using empty DataFrame for testing.
Process SpawnProcess-9:
Traceback (most recent call last):
  File "C:\Python313\Lib\multiprocessing\process.py", line 313, in _bootstrap
    self.run()
    ~~~~~~~~^^
  File "C:\Python313\Lib\multiprocessing\process.py", line 108, in run
    self._target(*self._args, **self._kwargs)
    ~~~~~~~~~~~~^^^^^^^^^^^^^^^^^^^^^^^^^^^^^
  File "C:\Users\sandv\AppData\Roaming\Python\Python313\site-packages\uvicorn\_subprocess.py", line 80, in subprocess_started
    target(sockets=sockets)
    ~~~~~~^^^^^^^^^^^^^^^^^
  File "C:\Users\sandv\AppData\Roaming\Python\Python313\site-packages\uvicorn\server.py", line 66, in run
    return asyncio.run(self.serve(sockets=sockets))
           ~~~~~~~~~~~^^^^^^^^^^^^^^^^^^^^^^^^^^^^^
  File "C:\Python313\Lib\asyncio\runners.py", line 194, in run
    return runner.run(main)
           ~~~~~~~~~~^^^^^^
  File "C:\Python313\Lib\asyncio\runners.py", line 118, in run
    return self._loop.run_until_complete(task)
           ~~~~~~~~~~~~~~~~~~~~~~~~~~~~~^^^^^^
  File "C:\Python313\Lib\asyncio\base_events.py", line 720, in run_until_complete
    return future.result()
           ~~~~~~~~~~~~~^^
  File "C:\Users\sandv\AppData\Roaming\Python\Python313\site-packages\uvicorn\server.py", line 70, in serve
    await self._serve(sockets)
  File "C:\Users\sandv\AppData\Roaming\Python\Python313\site-packages\uvicorn\server.py", line 77, in _serve
    config.load()
    ~~~~~~~~~~~^^
  File "C:\Users\sandv\AppData\Roaming\Python\Python313\site-packages\uvicorn\config.py", line 435, in load
    self.loaded_app = import_from_string(self.app)
                      ~~~~~~~~~~~~~~~~~~^^^^^^^^^^
  File "C:\Users\sandv\AppData\Roaming\Python\Python313\site-packages\uvicorn\importer.py", line 19, in import_from_string
    module = importlib.import_module(module_str)
  File "C:\Python313\Lib\importlib\__init__.py", line 88, in import_module
    return _bootstrap._gcd_import(name[level:], package, level)
           ~~~~~~~~~~~~~~~~~~~~~~^^^^^^^^^^^^^^^^^^^^^^^^^^^^^^
  File "<frozen importlib._bootstrap>", line 1387, in _gcd_import
  File "<frozen importlib._bootstrap>", line 1360, in _find_and_load
  File "<frozen importlib._bootstrap>", line 1331, in _find_and_load_unlocked
  File "<frozen importlib._bootstrap>", line 935, in _load_unlocked
  File "<frozen importlib._bootstrap_external>", line 1026, in exec_module
  File "<frozen importlib._bootstrap>", line 488, in _call_with_frames_removed
  File "C:\Users\sandv\Desktop\Outscaled2\backend\app\main.py", line 12, in <module>
    prediction_model = PredictionModel()
  File "C:\Users\sandv\Desktop\Outscaled2\backend\app\models\prediction_model.py", line 19, in __init__
    self._train_model()
    ~~~~~~~~~~~~~~~~~^^
  File "C:\Users\sandv\Desktop\Outscaled2\backend\app\models\prediction_model.py", line 26, in _train_model
    X, y, sample_weights = self._generate_real_training_data()
                           ~~~~~~~~~~~~~~~~~~~~~~~~~~~~~~~~~^^
  File "C:\Users\sandv\Desktop\Outscaled2\backend\app\models\prediction_model.py", line 88, in _generate_real_training_data
    all_players = data_processor.get_all_players()
  File "C:\Users\sandv\Desktop\Outscaled2\backend\app\utils\data_processor.py", line 811, in get_all_players
    all_players = combined_data['playername'].dropna().unique().tolist()
                  ~~~~~~~~~~~~~^^^^^^^^^^^^^^
  File "C:\Users\sandv\AppData\Roaming\Python\Python313\site-packages\pandas\core\frame.py", line 4107, in __getitem__
    indexer = self.columns.get_loc(key)
  File "C:\Users\sandv\AppData\Roaming\Python\Python313\site-packages\pandas\core\indexes\range.py", line 417, in get_loc
    raise KeyError(key)
KeyError: 'playername'
WARNING:  StatReload detected changes in 'app\utils\data_processor.py'. Reloading...
WARNING:app.utils.data_processor:Data files not found. Using empty DataFrame for testing.
INFO:app.models.prediction_model:Training prediction model...
WARNING:app.utils.data_processor:Data files not found. Using empty DataFrame for testing.
WARNING:app.utils.data_processor:No player data available
WARNING:app.models.prediction_model:No real training data available, falling back to rule-based model
WARNING:app.models.prediction_model:Using fallback training data - this should not be used in production
INFO:app.models.prediction_model:Training data shape: (1000, 21)
INFO:app.models.prediction_model:Class balance - OVER: 502 (50.2%), UNDER: 498 (49.8%)
INFO:app.models.prediction_model:Average sample weight: 0.500
INFO:app.models.prediction_model:Sample weight range: 0.500 - 0.500
C:\Users\sandv\AppData\Roaming\Python\Python313\site-packages\sklearn\calibration.py:333: UserWarning: The `cv='prefit'` option is deprecated in 1.6 and will be removed in 1.8. You can use CalibratedClassifierCV(FrozenEstimator(estimator)) instead.
  warnings.warn(
INFO:app.models.prediction_model:Calibration validation - Mean predicted probability: 0.500
INFO:app.models.prediction_model:Calibration validation - Actual OVER rate: 0.500
INFO:app.models.prediction_model:Calibration validation - Accuracy: 0.520
INFO:app.models.prediction_model:Calibration validation - Log loss: 0.685
INFO:app.models.prediction_model:Model training completed with real historical data
INFO:     Started server process [21336]
INFO:     Waiting for application startup.
INFO:     Application startup complete.
WARNING:  StatReload detected changes in 'app\utils\data_processor.py'. Reloading...
